<mujoco model='humanoid'>
  <compiler inertiafromgeom='true' angle='degree'/>

  <default>
    <joint limited='true' damping='1' armature='0'/>
    <geom contype='1' conaffinity='1' condim='1' rgba='0.8 0.6 .4 1'
      margin="0.001" solref=".02 1" solimp=".8 .8 .01" material="geom"/>
    <motor ctrlrange='-.4 .4' ctrllimited='true'/>
  </default>

  <option timestep='0.002' iterations="50" tolerance="1e-10" solver="Newton" jacobian="dense" cone="elliptic"/>

  <size nstack="1000000"/>

  <visual>
    <map fogstart="3" fogend="5" force="0.1" znear="0.5"/>
    <quality shadowsize="2048" offsamples="8"/>
    <global offwidth="800" offheight="800"/>
  </visual>

  <asset>
    <texture type="skybox" builtin="gradient" width="128" height="128" rgb1=".4 .6 .8"
        rgb2="0 0 0"/>
    <texture name="texgeom" type="cube" builtin="flat" mark="cross" width="127" height="1278"
        rgb1="0.8 0.6 0.4" rgb2="0.8 0.6 0.4" markrgb="1 1 1" random="0.01"/>
    <texture name="texplane" type="2d" builtin="checker" rgb1=".2 .3 .4" rgb2=".1 0.15 0.2"
        width="512" height="512"/>

    <material name='MatPlane' reflectance='0.3' texture="texplane" texrepeat="1 1" texuniform="true"/>
    <material name='geom' texture="texgeom" texuniform="true"/>
  </asset>

  <worldbody>
    <geom name='floor' pos='0 0 0' size='5 5 .125' type='plane' material="MatPlane" condim='3'/>

    <light mode='targetbodycom' target='torso' directional='false' diffuse='.7 .7 .7' ambient='.3 .3 .3' pos='0 0 4.0' dir='0 0 -1'/>

    <camera name='targeting' pos='1 1 2' mode='targetbodycom' target='torso'/>
    
    
    <body name='torso' pos='0 0 1.4'>

      <camera name='tracking' pos='1 1 2' zaxis="1 2 3" mode='trackcom'/>

      <site name='root' pos='0 0 0' type='sphere' group='4' size='0.06'/>
      <freejoint name="root"/>
      <geom name='torso1' type='capsule' fromto='0 -.07 0 0 .07 0'  size='0.07'/>
      <geom name='head' type='sphere' pos='0 0 .19' size='.09'/>
      <geom name='uwaist' type='capsule' fromto='-.01 -.06 -.12 -.01 .06 -.12' size='0.06'/>
      <body name='lwaist' pos='-.01 0 -0.260' quat='1.000 0 -0.002 0' >
        <geom name='lwaist' type='capsule' fromto='0 -.06 0 0 .06 0'  size='0.06' />
        <site name='abdomen_z' pos='0 0 0.065' type='sphere' group='4' size='0.06'/>
        <site name='abdomen_y' pos='0 0 0.065' type='sphere' group='4' size='0.06'/>
        <joint name='abdomen_z' type='hinge' pos='0 0 0.065' axis='0 0 1' range='-45 45' damping='5' stiffness='20' armature='0.02' />
        <joint name='abdomen_y' type='hinge' pos='0 0 0.065' axis='0 1 0' range='-75 30' damping='5' stiffness='10' armature='0.02' />
        <body name='pelvis' pos='0 0 -0.165' quat='1.000 0 -0.002 0' >
          <site name='abdomen_x' pos='0 0 0.1' type='sphere' group='4' size='0.06'/>
          <joint name='abdomen_x' type='hinge' pos='0 0 0.1' axis='1 0 0' range='-35 35' damping='5' stiffness='10' armature='0.02' />
          <geom name='butt' type='capsule' fromto='-.02 -.07 0 -.02 .07 0'  size='0.09' />
          <body name='right_thigh' pos='0 -0.1 -0.04' >
            <site name='right_hip_x' pos='0 0 0' type='sphere' group='4' size='0.06'/>
            <site name='right_hip_z' pos='0 0 0' type='sphere' group='4' size='0.06'/>
            <site name='right_hip_y' pos='0 0 0' type='sphere' group='4' size='0.06'/>
            <joint name='right_hip_x' type='hinge' pos='0 0 0' axis='1 0 0' range='-25 5'   damping='5' stiffness='10' armature='0.01' />
            <joint name='right_hip_z' type='hinge' pos='0 0 0' axis='0 0 1' range='-60 35'  damping='5' stiffness='10' armature='0.01' />
            <joint name='right_hip_y' type='hinge' pos='0 0 0' axis='0 1 0' range='-120 20' damping='5' stiffness='20' armature='0.01' />
            <geom name='right_thigh1' type='capsule' fromto='0 0 0 0 0.01 -.34'  size='0.06' />
            <body name='right_shin' pos='0 0.01 -0.403' >
              <site name='right_knee' pos='0 0 0.02' type='sphere' group='4' size='0.06'/>
              <joint name='right_knee' type='hinge' pos='0 0 .02' axis='0 -1 0' range='-160 -2' stiffness='1' armature='0.0060' />
              <geom name='right_shin1' type='capsule' fromto='0 0 0 0 0 -.3'   size='0.049' />
              <body name='right_foot' pos='0 0 -.39' >
                <site name='right_ankle_y' pos='0 0 0.08' type='sphere' group='4' size='0.06'/>
                <site name='right_ankle_x' pos='0 0 0.04' type='sphere' group='4' size='0.06'/>
                <joint name='right_ankle_y' type='hinge' pos='0 0 0.08' axis='0 1 0'   range='-50 50' stiffness='4' armature='0.0008' />
                <joint name='right_ankle_x' type='hinge' pos='0 0 0.04' axis='1 0 0.5' range='-50 50' stiffness='1'  armature='0.0006' />
                <geom name='right_foot_cap1' type='capsule' fromto='-.07 -0.02 0 0.14 -0.04 0'  size='0.027' />
                <geom name='right_foot_cap2' type='capsule' fromto='-.07 0 0 0.14  0.02 0'  size='0.027' />
              </body>
            </body>
          </body>
          <body name='left_thigh' pos='0 0.1 -0.04' >
            <site name='left_hip_x' pos='0 0 0' type='sphere' group='4' size='0.06'/>
            <site name='left_hip_z' pos='0 0 0' type='sphere' group='4' size='0.06'/>
            <site name='left_hip_y' pos='0 0 0' type='sphere' group='4' size='0.06'/>
            <joint name='left_hip_x' type='hinge' pos='0 0 0' axis='-1 0 0' range='-25 5'  damping='5' stiffness='10' armature='0.01' />
            <joint name='left_hip_z' type='hinge' pos='0 0 0' axis='0 0 -1' range='-60 35' damping='5' stiffness='10' armature='0.01' />
            <joint name='left_hip_y' type='hinge' pos='0 0 0' axis='0 1 0' range='-120 20' damping='5' stiffness='20' armature='0.01' />
            <geom name='left_thigh1' type='capsule' fromto='0 0 0 0 -0.01 -.34'  size='0.06' />
            <body name='left_shin' pos='0 -0.01 -0.403' >
              <site name='left_knee' pos='0 0 0.02' type='sphere' group='4' size='0.06'/>
              <joint name='left_knee' type='hinge' pos='0 0 .02' axis='0 -1 0' range='-160 -2' stiffness='1' armature='0.0060' />
              <geom name='left_shin1' type='capsule' fromto='0 0 0 0 0 -.3'   size='0.049' />
              <body name='left_foot' pos='0 0 -.39' >
                <site name='left_ankle_y' pos='0 0 0.08' type='sphere' group='4' size='0.06'/>
                <site name='left_ankle_x' pos='0 0 0.04' type='sphere' group='4' size='0.06'/>
                <joint name='left_ankle_y' type='hinge' pos='0 0 0.08' axis='0 1 0'   range='-50 50'  stiffness='4' armature='0.0008' />
                <joint name='left_ankle_x' type='hinge' pos='0 0 0.04' axis='1 0 0.5' range='-50 50'  stiffness='1'  armature='0.0006' />
                <geom name='left_foot_cap1' type='capsule' fromto='-.07 0.02 0 0.14 0.04 0'  size='0.027' />
                <geom name='left_foot_cap2' type='capsule' fromto='-.07 0 0 0.14  -0.02 0'  size='0.027' />
              </body>
            </body>
          </body>
        </body>
      </body>
      <body name='right_upper_arm' pos='0 -0.17 0.06' >
        <site name='right_shoulder1' pos='0 0 0' type='sphere' group='4' size='0.06'/>
        <site name='right_shoulder2' pos='0 0 0' type='sphere' group='4' size='0.06'/>
        <joint name='right_shoulder1' type='hinge' pos='0 0 0' axis='2 1 1'  range='-85 60' stiffness='1' armature='0.0068' />
        <joint name='right_shoulder2' type='hinge' pos='0 0 0' axis='0 -1 1' range='-85 60' stiffness='1'  armature='0.0051' />
        <geom name='right_uarm1' type='capsule' fromto='0 0 0 .16 -.16 -.16'  size='0.04 0.16' />
        <body name='right_lower_arm' pos='.18 -.18 -.18' >
          <site name='right_elbow' pos='0 0 0' type='sphere' group='4' size='0.06'/>
          <joint name='right_elbow' type='hinge' pos='0 0 0' axis='0 -1 1' range='-90 50'  stiffness='0' armature='0.0028' />
          <geom name='right_larm' type='capsule' fromto='0.01 0.01 0.01 .17 .17 .17'  size='0.031' />
          <geom name='right_hand' type='sphere' pos='.18 .18 .18'  size='0.04'/>
        </body>
      </body>
      <body name='left_upper_arm' pos='0 0.17 0.06' >
        <site name='left_shoulder1' pos='0 0 0' type='sphere' group='4' size='0.06'/>
        <site name='left_shoulder2' pos='0 0 0' type='sphere' group='4' size='0.06'/>
        <joint name='left_shoulder1' type='hinge' pos='0 0 0' axis='2 -1 1' range='-60 85' stiffness='1' armature='0.0068' />
        <joint name='left_shoulder2' type='hinge' pos='0 0 0' axis='0 1 1' range='-60 85'  stiffness='1' armature='0.0051' />
        <geom name='left_uarm1' type='capsule' fromto='0 0 0 .16 .16 -.16'  size='0.04 0.16' />
        <body name='left_lower_arm' pos='.18 .18 -.18' >
          <site name='left_elbow' pos='0 0 0' type='sphere' group='4' size='0.06'/>
          <joint name='left_elbow' type='hinge' pos='0 0 0' axis='0 -1 -1' range='-90 50' stiffness='0' armature='0.0028' />
          <geom name='left_larm' type='capsule' fromto='0.01 -0.01 0.01 .17 -.17 .17'  size='0.031' />
          <geom name='left_hand' type='sphere' pos='.18 -.18 .18'  size='0.04'/>
        </body>
      </body>
    </body>
  </worldbody>

  <actuator>
    <motor name='abdomen_y'       gear='200' joint='abdomen_y' />
    <motor name='abdomen_z'       gear='200' joint='abdomen_z' />
    <motor name='abdomen_x'       gear='200' joint='abdomen_x' />
    <motor name='right_hip_x'     gear='200' joint='right_hip_x' />
    <motor name='right_hip_z'     gear='200' joint='right_hip_z' />
    <motor name='right_hip_y'     gear='600' joint='right_hip_y' />
    <motor name='right_knee'      gear='400' joint='right_knee' />
    <motor name='right_ankle_x'   gear='100' joint='right_ankle_x' />
    <motor name='right_ankle_y'   gear='100' joint='right_ankle_y' />
    <motor name='left_hip_x'      gear='200' joint='left_hip_x' />
    <motor name='left_hip_z'      gear='200' joint='left_hip_z' />
    <motor name='left_hip_y'      gear='600' joint='left_hip_y' />
    <motor name='left_knee'       gear='400' joint='left_knee' />
    <motor name='left_ankle_x'    gear='100' joint='left_ankle_x' />
    <motor name='left_ankle_y'    gear='100' joint='left_ankle_y' />
    <motor name='right_shoulder1' gear='100' joint='right_shoulder1' />
    <motor name='right_shoulder2' gear='100' joint='right_shoulder2' />
    <motor name='right_elbow'     gear='200' joint='right_elbow' />
    <motor name='left_shoulder1'  gear='100' joint='left_shoulder1' />
    <motor name='left_shoulder2'  gear='100' joint='left_shoulder2' />
    <motor name='left_elbow'      gear='200' joint='left_elbow' />
  </actuator>
  <sensor>
    <jointpos name='jp_abdomen_z'           joint='abdomen_z'/>
    <jointpos name='jp_abdomen_y'           joint='abdomen_y'/>
    <jointpos name='jp_abdomen_x'           joint='abdomen_x'/>
    <jointpos name='jp_right_hip_x'         joint='right_hip_x'/>
    <jointpos name='jp_right_hip_z'         joint='right_hip_z'/>
    <jointpos name='jp_right_hip_y'         joint='right_hip_y'/>
    <jointpos name='jp_right_knee'          joint='right_knee'/>
    <jointpos name='jp_right_ankle_y'       joint='right_ankle_y'/>
    <jointpos name='jp_right_ankle_x'       joint='right_ankle_x'/>
    <jointpos name='jp_left_hip_x'          joint='left_hip_x'/>
    <jointpos name='jp_left_hip_z'          joint='left_hip_z'/>
    <jointpos name='jp_left_hip_y'          joint='left_hip_y'/>
    <jointpos name='jp_left_knee'           joint='left_knee'/>
    <jointpos name='jp_left_ankle_y'        joint='left_ankle_y'/>
    <jointpos name='jp_left_ankle_x'        joint='left_ankle_x'/>
    <jointpos name='jp_right_shoulder1'     joint='right_shoulder1'/>
    <jointpos name='jp_right_shoulder2'     joint='right_shoulder2'/>
    <jointpos name='jp_right_elbow'         joint='right_elbow'/>
    <jointpos name='jp_left_shoulder1'      joint='left_shoulder1'/>
    <jointpos name='jp_left_shoulder2'      joint='left_shoulder2'/>
    <jointpos name='jp_left_elbow'          joint='left_elbow'/>
    
    <jointvel name='jv_abdomen_z'           joint='abdomen_z'/>
    <jointvel name='jv_abdomen_y'           joint='abdomen_y'/>
    <jointvel name='jv_abdomen_x'           joint='abdomen_x'/>
    <jointvel name='jv_right_hip_x'         joint='right_hip_x'/>
    <jointvel name='jv_right_hip_z'         joint='right_hip_z'/>
    <jointvel name='jv_right_hip_y'         joint='right_hip_y'/>
    <jointvel name='jv_right_knee'          joint='right_knee'/>
    <jointvel name='jv_right_ankle_y'       joint='right_ankle_y'/>
    <jointvel name='jv_right_ankle_x'       joint='right_ankle_x'/>
    <jointvel name='jv_left_hip_x'          joint='left_hip_x'/>
    <jointvel name='jv_left_hip_z'          joint='left_hip_z'/>
    <jointvel name='jv_left_hip_y'          joint='left_hip_y'/>
    <jointvel name='jv_left_knee'           joint='left_knee'/>
    <jointvel name='jv_left_ankle_y'        joint='left_ankle_y'/>
    <jointvel name='jv_left_ankle_x'        joint='left_ankle_x'/>
    <jointvel name='jv_right_shoulder1'     joint='right_shoulder1'/>
    <jointvel name='jv_right_shoulder2'     joint='right_shoulder2'/>
    <jointvel name='jv_right_elbow'         joint='right_elbow'/>
    <jointvel name='jv_left_shoulder1'      joint='left_shoulder1'/>
    <jointvel name='jv_left_shoulder2'      joint='left_shoulder2'/>
    <jointvel name='jv_left_elbow'          joint='left_elbow'/>
    
    <accelerometer  name='a_abdomen_z'           site='abdomen_z'/>
    <accelerometer  name='a_abdomen_y'           site='abdomen_y'/>
    <accelerometer  name='a_abdomen_x'           site='abdomen_x'/>
    <accelerometer  name='a_right_hip_x'         site='right_hip_x'/>
    <accelerometer  name='a_right_hip_z'         site='right_hip_z'/>
    <accelerometer  name='a_right_hip_y'         site='right_hip_y'/>
    <accelerometer  name='a_right_knee'          site='right_knee'/>
    <accelerometer  name='a_right_ankle_y'       site='right_ankle_y'/>
    <accelerometer  name='a_right_ankle_x'       site='right_ankle_x'/>
    <accelerometer  name='a_left_hip_x'          site='left_hip_x'/>
    <accelerometer  name='a_left_hip_z'          site='left_hip_z'/>
    <accelerometer  name='a_left_hip_y'          site='left_hip_y'/>
    <accelerometer  name='a_left_knee'           site='left_knee'/>
    <accelerometer  name='a_left_ankle_y'        site='left_ankle_y'/>
    <accelerometer  name='a_left_ankle_x'        site='left_ankle_x'/>
    <accelerometer  name='a_right_shoulder1'     site='right_shoulder1'/>
    <accelerometer  name='a_right_shoulder2'     site='right_shoulder2'/>
    <accelerometer  name='a_right_elbow'         site='right_elbow'/>
    <accelerometer  name='a_left_shoulder1'      site='left_shoulder1'/>
    <accelerometer  name='a_left_shoulder2'      site='left_shoulder2'/>
    <accelerometer  name='a_left_elbow'          site='left_elbow'/>
    
    <velocimeter  name='v_abdomen_z'           site='abdomen_z'/>
    <velocimeter  name='v_abdomen_y'           site='abdomen_y'/>
    <velocimeter  name='v_abdomen_x'           site='abdomen_x'/>
    <velocimeter  name='v_right_hip_x'         site='right_hip_x'/>
    <velocimeter  name='v_right_hip_z'         site='right_hip_z'/>
    <velocimeter  name='v_right_hip_y'         site='right_hip_y'/>
    <velocimeter  name='v_right_knee'          site='right_knee'/>
    <velocimeter  name='v_right_ankle_y'       site='right_ankle_y'/>
    <velocimeter  name='v_right_ankle_x'       site='right_ankle_x'/>
    <velocimeter  name='v_left_hip_x'          site='left_hip_x'/>
    <velocimeter  name='v_left_hip_z'          site='left_hip_z'/>
    <velocimeter  name='v_left_hip_y'          site='left_hip_y'/>
    <velocimeter  name='v_left_knee'           site='left_knee'/>
    <velocimeter  name='v_left_ankle_y'        site='left_ankle_y'/>
    <velocimeter  name='v_left_ankle_x'        site='left_ankle_x'/>
    <velocimeter  name='v_right_shoulder1'     site='right_shoulder1'/>
    <velocimeter  name='v_right_shoulder2'     site='right_shoulder2'/>
    <velocimeter  name='v_right_elbow'         site='right_elbow'/>
    <velocimeter  name='v_left_shoulder1'      site='left_shoulder1'/>
    <velocimeter  name='v_left_shoulder2'      site='left_shoulder2'/>
    <velocimeter  name='v_left_elbow'          site='left_elbow'/>
    
    <gyro  name='g_abdomen_z'           site='abdomen_z'/>
    <gyro  name='g_abdomen_y'           site='abdomen_y'/>
    <gyro  name='g_abdomen_x'           site='abdomen_x'/>
    <gyro  name='g_right_hip_x'         site='right_hip_x'/>
    <gyro  name='g_right_hip_z'         site='right_hip_z'/>
    <gyro  name='g_right_hip_y'         site='right_hip_y'/>
    <gyro  name='g_right_knee'          site='right_knee'/>
    <gyro  name='g_right_ankle_y'       site='right_ankle_y'/>
    <gyro  name='g_right_ankle_x'       site='right_ankle_x'/>
    <gyro  name='g_left_hip_x'          site='left_hip_x'/>
    <gyro  name='g_left_hip_z'          site='left_hip_z'/>
    <gyro  name='g_left_hip_y'          site='left_hip_y'/>
    <gyro  name='g_left_knee'           site='left_knee'/>
    <gyro  name='g_left_ankle_y'        site='left_ankle_y'/>
    <gyro  name='g_left_ankle_x'        site='left_ankle_x'/>
    <gyro  name='g_right_shoulder1'     site='right_shoulder1'/>
    <gyro  name='g_right_shoulder2'     site='right_shoulder2'/>
    <gyro  name='g_right_elbow'         site='right_elbow'/>
    <gyro  name='g_left_shoulder1'      site='left_shoulder1'/>
    <gyro  name='g_left_shoulder2'      site='left_shoulder2'/>
    <gyro  name='g_left_elbow'          site='left_elbow'/>
    
    <force  name='f_abdomen_z'           site='abdomen_z'/>
    <force  name='f_abdomen_y'           site='abdomen_y'/>
    <force  name='f_abdomen_x'           site='abdomen_x'/>
    <force  name='f_right_hip_x'         site='right_hip_x'/>
    <force  name='f_right_hip_z'         site='right_hip_z'/>
    <force  name='f_right_hip_y'         site='right_hip_y'/>
    <force  name='f_right_knee'          site='right_knee'/>
    <force  name='f_right_ankle_y'       site='right_ankle_y'/>
    <force  name='f_right_ankle_x'       site='right_ankle_x'/>
    <force  name='f_left_hip_x'          site='left_hip_x'/>
    <force  name='f_left_hip_z'          site='left_hip_z'/>
    <force  name='f_left_hip_y'          site='left_hip_y'/>
    <force  name='f_left_knee'           site='left_knee'/>
    <force  name='f_left_ankle_y'        site='left_ankle_y'/>
    <force  name='f_left_ankle_x'        site='left_ankle_x'/>
    <force  name='f_right_shoulder1'     site='right_shoulder1'/>
    <force  name='f_right_shoulder2'     site='right_shoulder2'/>
    <force  name='f_right_elbow'         site='right_elbow'/>
    <force  name='f_left_shoulder1'      site='left_shoulder1'/>
    <force  name='f_left_shoulder2'      site='left_shoulder2'/>
    <force  name='f_left_elbow'          site='left_elbow'/>
    
    <torque  name='t_abdomen_z'           site='abdomen_z'/>
    <torque  name='t_abdomen_y'           site='abdomen_y'/>
    <torque  name='t_abdomen_x'           site='abdomen_x'/>
    <torque  name='t_right_hip_x'         site='right_hip_x'/>
    <torque  name='t_right_hip_z'         site='right_hip_z'/>
    <torque  name='t_right_hip_y'         site='right_hip_y'/>
    <torque  name='t_right_knee'          site='right_knee'/>
    <torque  name='t_right_ankle_y'       site='right_ankle_y'/>
    <torque  name='t_right_ankle_x'       site='right_ankle_x'/>
    <torque  name='t_left_hip_x'          site='left_hip_x'/>
    <torque  name='t_left_hip_z'          site='left_hip_z'/>
    <torque  name='t_left_hip_y'          site='left_hip_y'/>
    <torque  name='t_left_knee'           site='left_knee'/>
    <torque  name='t_left_ankle_y'        site='left_ankle_y'/>
    <torque  name='t_left_ankle_x'        site='left_ankle_x'/>
    <torque  name='t_right_shoulder1'     site='right_shoulder1'/>
    <torque  name='t_right_shoulder2'     site='right_shoulder2'/>
    <torque  name='t_right_elbow'         site='right_elbow'/>
    <torque  name='t_left_shoulder1'      site='left_shoulder1'/>
    <torque  name='t_left_shoulder2'      site='left_shoulder2'/>
    <torque  name='t_left_elbow'          site='left_elbow'/>
  
    <!--<touch name="s_t1"	site="t1"/>-->
  </sensor>
</mujoco>
